Workbook

Sheet Tong_quan
A1: # | B1: Chủ đề | C1: Sheet | D1: Số nhóm con | E1: Tổng số mục
A2: 1 | B2: Chào hỏi, lịch sự | C2: T01_ChaoHoi | D2: 6 | E2: =COUNTA(T01_ChaoHoi!B2:B400) -> 58
A3: 2 | B3: Thông tin cá nhân | C3: T02_ThongTin | D3: 7 | E3: =COUNTA(T02_ThongTin!B2:B400) -> 94
A4: 3 | B4: Nghề nghiệp | C4: T03_NgheNghiep | D4: 8 | E4: =COUNTA(T03_NgheNghiep!B2:B400) -> 66
A5: 4 | B5: Gia đình | C5: T04_GiaDinh | D5: 7 | E5: =COUNTA(T04_GiaDinh!B2:B400) -> 62
A6: 5 | B6: Thời gian | C6: T05_ThoiGian | D6: 9 | E6: =COUNTA(T05_ThoiGian!B2:B400) -> 64
A7: 6 | B7: Hoạt động hằng ngày | C7: T06_HangNgay | D7: 7 | E7: =COUNTA(T06_HangNgay!B2:B400) -> 59
A8: 7 | B8: Nhà cửa | C8: T07_NhaCua | D8: 8 | E8: =COUNTA(T07_NhaCua!B2:B400) -> 70
A9: 8 | B9: Thành phố, chỉ đường, giao thông | C9: T08_ThanhPho | D9: 9 | E9: =COUNTA(T08_ThanhPho!B2:B400) -> 89
A10: 9 | B10: Màu sắc, quần áo, miêu tả | C10: T09_QuanAo | D10: 8 | E10: =COUNTA(T09_QuanAo!B2:B400) -> 84
A11: 10 | B11: Đồ ăn thức uống, mua sắm, tiền | C11: T10_AnUong | D11: 11 | E11: =COUNTA(T10_AnUong!B2:B400) -> 118
A12: 11 | B12: Sở thích, thời tiết, kỳ nghỉ | C12: T11_SoThich | D12: 5 | E12: =COUNTA(T11_SoThich!B2:B400) -> 94
B13: Tổng | D13: =SUM(D2:D12) -> 85 | E13: =SUM(E2:E12) -> 858

Sheet Cau_truc
A1: # | B1: Chủ đề | C1: Nhóm con | D1: Số mục
A2: 1 | B2: Chào hỏi, lịch sự | C2: Chào hỏi, tạm biệt | D2: =COUNTIF(T01_ChaoHoi!$A$2:$A$400,C2) -> 8
A3: 1 | B3: Chào hỏi, lịch sự | C3: Hỏi thăm | D3: =COUNTIF(T01_ChaoHoi!$A$2:$A$400,C3) -> 4
A4: 1 | B4: Chào hỏi, lịch sự | C4: Cảm ơn, xin lỗi, nhờ vả | D4: =COUNTIF(T01_ChaoHoi!$A$2:$A$400,C4) -> 13
A5: 1 | B5: Chào hỏi, lịch sự | C5: Xưng hô, đáp lời | D5: =COUNTIF(T01_ChaoHoi!$A$2:$A$400,C5) -> 9
A6: 1 | B6: Chào hỏi, lịch sự | C6: Lời chúc | D6: =COUNTIF(T01_ChaoHoi!$A$2:$A$400,C6) -> 16
A7: 1 | B7: Chào hỏi, lịch sự | C7: Giới thiệu, đón tiếp | D7: =COUNTIF(T01_ChaoHoi!$A$2:$A$400,C7) -> 8
A8: 2 | B8: Thông tin cá nhân | C8: Họ tên, tuổi, nơi sinh | D8: =COUNTIF(T02_ThongTin!$A$2:$A$400,C8) -> 11
A9: 2 | B9: Thông tin cá nhân | C9: Địa chỉ, liên lạc | D9: =COUNTIF(T02_ThongTin!$A$2:$A$400,C9) -> 8
A10: 2 | B10: Thông tin cá nhân | C10: Tình trạng gia đình | D10: =COUNTIF(T02_ThongTin!$A$2:$A$400,C10) -> 5
A11: 2 | B11: Thông tin cá nhân | C11: Giấy tờ, biểu mẫu | D11: =COUNTIF(T02_ThongTin!$A$2:$A$400,C11) -> 8
A12: 2 | B12: Thông tin cá nhân | C12: Quốc gia và quốc tịch | D12: =COUNTIF(T02_ThongTin!$A$2:$A$400,C12) -> 43
A13: 2 | B13: Thông tin cá nhân | C13: Ngôn ngữ | D13: =COUNTIF(T02_ThongTin!$A$2:$A$400,C13) -> 12
A14: 2 | B14: Thông tin cá nhân | C14: Châu lục, địa lý cơ bản | D14: =COUNTIF(T02_ThongTin!$A$2:$A$400,C14) -> 7
A15: 3 | B15: Nghề nghiệp | C15: Khái niệm chung về nghề | D15: =COUNTIF(T03_NgheNghiep!$A$2:$A$400,C15) -> 16
A16: 3 | B16: Nghề nghiệp | C16: Học tập, giáo dục | D16: =COUNTIF(T03_NgheNghiep!$A$2:$A$400,C16) -> 5
A17: 3 | B17: Nghề nghiệp | C17: Y tế | D17: =COUNTIF(T03_NgheNghiep!$A$2:$A$400,C17) -> 7
A18: 3 | B18: Nghề nghiệp | C18: Văn phòng, luật, kỹ thuật | D18: =COUNTIF(T03_NgheNghiep!$A$2:$A$400,C18) -> 10
A19: 3 | B19: Nghề nghiệp | C19: Dịch vụ, bán hàng, ăn uống | D19: =COUNTIF(T03_NgheNghiep!$A$2:$A$400,C19) -> 7
A20: 3 | B20: Nghề nghiệp | C20: An ninh, giao thông, lao động chân tay | D20: =COUNTIF(T03_NgheNghiep!$A$2:$A$400,C20) -> 10
A21: 3 | B21: Nghề nghiệp | C21: Truyền thông, nghệ thuật | D21: =COUNTIF(T03_NgheNghiep!$A$2:$A$400,C21) -> 4
A22: 3 | B22: Nghề nghiệp | C22: Tình trạng việc làm | D22: =COUNTIF(T03_NgheNghiep!$A$2:$A$400,C22) -> 7
A23: 4 | B23: Gia đình | C23: Gia đình hạt nhân | D23: =COUNTIF(T04_GiaDinh!$A$2:$A$400,C23) -> 12
A24: 4 | B24: Gia đình | C24: Ông bà, cháu | D24: =COUNTIF(T04_GiaDinh!$A$2:$A$400,C24) -> 8
A25: 4 | B25: Gia đình | C25: Họ hàng | D25: =COUNTIF(T04_GiaDinh!$A$2:$A$400,C25) -> 8
A26: 4 | B26: Gia đình | C26: Vợ chồng, nhà vợ/chồng | D26: =COUNTIF(T04_GiaDinh!$A$2:$A$400,C26) -> 11
A27: 4 | B27: Gia đình | C27: Độ tuổi, các giai đoạn cuộc đời | D27: =COUNTIF(T04_GiaDinh!$A$2:$A$400,C27) -> 14
A28: 4 | B28: Gia đình | C28: Bạn bè | D28: =COUNTIF(T04_GiaDinh!$A$2:$A$400,C28) -> 3
A29: 4 | B29: Gia đình | C29: Tình yêu, hôn nhân, sinh nhật | D29: =COUNTIF(T04_GiaDinh!$A$2:$A$400,C29) -> 6
A30: 5 | B30: Thời gian | C30: Đơn vị thời gian | D30: =COUNTIF(T05_ThoiGian!$A$2:$A$400,C30) -> 5
A31: 5 | B31: Thời gian | C31: Các ngày trong tuần | D31: =COUNTIF(T05_ThoiGian!$A$2:$A$400,C31) -> 8
A32: 5 | B32: Thời gian | C32: Các tháng | D32: =COUNTIF(T05_ThoiGian!$A$2:$A$400,C32) -> 12
A33: 5 | B33: Thời gian | C33: Các mùa | D33: =COUNTIF(T05_ThoiGian!$A$2:$A$400,C33) -> 5
A34: 5 | B34: Thời gian | C34: Các buổi trong ngày | D34: =COUNTIF(T05_ThoiGian!$A$2:$A$400,C34) -> 5
A35: 5 | B35: Thời gian | C35: Giờ giấc | D35: =COUNTIF(T05_ThoiGian!$A$2:$A$400,C35) -> 10
A36: 5 | B36: Thời gian | C36: Trạng từ thời gian | D36: =COUNTIF(T05_ThoiGian!$A$2:$A$400,C36) -> 9
A37: 5 | B37: Thời gian | C37: Đồng hồ, đúng giờ, trễ | D37: =COUNTIF(T05_ThoiGian!$A$2:$A$400,C37) -> 6
A38: 5 | B38: Thời gian | C38: Lễ, ngày nghỉ, cuộc hẹn | D38: =COUNTIF(T05_ThoiGian!$A$2:$A$400,C38) -> 4
A39: 6 | B39: Hoạt động hằng ngày | C39: Buổi sáng, vệ sinh cá nhân | D39: =COUNTIF(T06_HangNgay!$A$2:$A$400,C39) -> 10
A40: 6 | B40: Hoạt động hằng ngày | C40: Bữa ăn | D40: =COUNTIF(T06_HangNgay!$A$2:$A$400,C40) -> 5
...

Sheet T01_ChaoHoi
A1: Nhóm con | B1: Tiếng Pháp | C1: Loại từ | D1: Nghĩa tiếng Việt | E1: Ghi chú
A2: Chào hỏi, tạm biệt | B2: bonjour | C2: interj | D2: xin chào (ban ngày)
A3: Chào hỏi, tạm biệt | B3: bonsoir | C3: interj | D3: chào buổi tối
A4: Chào hỏi, tạm biệt | B4: salut | C4: interj | D4: chào (thân mật) | E4: thân mật; dùng khi gặp và khi chia tay
A5: Chào hỏi, tạm biệt | B5: au revoir | C5: expr | D5: tạm biệt
A6: Chào hỏi, tạm biệt | B6: à bientôt | C6: expr | D6: hẹn sớm gặp lại
A7: Chào hỏi, tạm biệt | B7: à demain | C7: expr | D7: hẹn mai gặp
A8: Chào hỏi, tạm biệt | B8: bienvenue | C8: interj | D8: chào mừng
A9: Chào hỏi, tạm biệt | B9: à tout à l'heure | C9: expr | D9: hẹn lát nữa gặp
A10: Hỏi thăm | B10: Comment allez-vous ? | C10: expr | D10: Ông/bà/bạn khỏe không? (trang trọng)
A11: Hỏi thăm | B11: Ça va ? | C11: expr | D11: Khỏe không? (thân mật)
A12: Hỏi thăm | B12: Ça va bien. | C12: expr | D12: Tôi khỏe.
A13: Hỏi thăm | B13: Et vous ? / Et toi ? | C13: expr | D13: Còn bạn thì sao?
A14: Cảm ơn, xin lỗi, nhờ vả | B14: merci | C14: interj | D14: cảm ơn
A15: Cảm ơn, xin lỗi, nhờ vả | B15: merci beaucoup | C15: expr | D15: cảm ơn nhiều
A16: Cảm ơn, xin lỗi, nhờ vả | B16: de rien | C16: expr | D16: không có gì
... A31: Xưng hô, đáp lời | B31: mademoiselle | C31: nf | D31: cô
A32: Xưng hô, đáp lời | B32: tu | C32: pron | D32: bạn (thân mật) | E32: dùng với bạn bè, người nhà, trẻ em
A33: Xưng hô, đáp lời | B33: vous | C33: pron | D33: ông/bà/các bạn (trang trọng hoặc số nhiều)
A34: Xưng hô, đáp lời | B34: poli / polie | C34: adj | D34: lịch sự
A35: Xưng hô, đáp lời | B35: impoli / impolie | C35: adj | D35: bất lịch sự
A36: Lời chúc | B36: bonne journée | C36: expr | D36: chúc một ngày tốt lành
A37: Lời chúc | B37: bonne soirée | C37: expr | D37: chúc buổi tối vui vẻ
A38: Lời chúc | B38: bonne nuit | C38: expr | D38: chúc ngủ ngon
A39: Lời chúc | B39: félicitations | C39: nfpl | D39: xin chúc mừng
A40: Lời chúc | B40: joyeux anniversaire | C40: expr | D40: chúc mừng sinh nhật
A41: Lời chúc | B41: bonne chance | C41: expr | D41: chúc may mắn
A42: Lời chúc | B42: bon appétit | C42: expr | D42: chúc ngon miệng
A43: Lời chúc | B43: santé ! | C43: interj | D43: cạn ly; chúc sức khỏe
A44: Lời chúc | B44: bon week-end | C44: expr | D44: chúc cuối tuần vui vẻ
... A52: Giới thiệu, đón tiếp | B52: enchanté / enchantée | C52: adj | D52: rất vui được gặp
A53: Giới thiệu, đón tiếp | B53: présenter | C53: v | D53: giới thiệu | E53: Je vous présente Anna.
A54: Giới thiệu, đón tiếp | B54: entrer | C54: v | D54: vào | E54: Entrez, je vous en prie !
A55: Giới thiệu, đón tiếp | B55: s'asseoir | C55: v | D55: ngồi xuống | E55: Asseyez-vous !
A56: Giới thiệu, đón tiếp | B56: content / contente | C56: adj | D56: vui, hài lòng
A57: Giới thiệu, đón tiếp | B57: Ça me fait plaisir. | C57: expr | D57: Tôi rất vui.
A58: Giới thiệu, đón tiếp | B58: serrer la main | C58: expr | D58: bắt tay
A59: Giới thiệu, đón tiếp | B59: faire la bise | C59: expr | D59: hôn má chào | E59: thân mật

Sheet T02_ThongTin
A1: Nhóm con | B1: Tiếng Pháp | C1: Loại từ | D1: Nghĩa tiếng Việt | E1: Ghi chú
A2: Họ tên, tuổi, nơi sinh | B2: le nom | C2: nm | D2: tên (họ tên)
A3: Họ tên, tuổi, nơi sinh | B3: le nom de famille | C3: nm | D3: họ
A4: Họ tên, tuổi, nơi sinh | B4: le prénom | C4: nm | D4: tên riêng
A5: Họ tên, tuổi, nơi sinh | B5: l'âge | C5: nm | D5: tuổi
A6: Họ tên, tuổi, nơi sinh | B6: avoir … ans | C6: expr | D6: … tuổi | E6: J'ai 25 ans.
A7: Họ tên, tuổi, nơi sinh | B7: la date de naissance | C7: nf | D7: ngày sinh
A8: Họ tên, tuổi, nơi sinh | B8: le lieu de naissance | C8: nm | D8: nơi sinh
A9: Họ tên, tuổi, nơi sinh | B9: s'appeler | C9: v | D9: tên là | E9: Je m'appelle Linh.
A10: Họ tên, tuổi, nơi sinh | B10: être né / née à | C10: expr | D10: sinh ra ở
A11: Họ tên, tuổi, nơi sinh | B11: épeler | C11: v | D11: đánh vần
A12: Họ tên, tuổi, nơi sinh | B12: le sexe | C12: nm | D12: giới tính
A13: Địa chỉ, liên lạc | B13: l'adresse | C13: nf | D13: địa chỉ
A14: Địa chỉ, liên lạc | B14: le numéro de téléphone | C14: nm | D14: số điện thoại
A15: Địa chỉ, liên lạc | B15: l'adresse e-mail | C15: nf | D15: địa chỉ e-mail
A16: Địa chỉ, liên lạc | B16: le code postal | C16: nm | D16: mã bưu chính
A17: Địa chỉ, liên lạc | B17: habiter | C17: v | D17: sống, ở | E17: J'habite à Hanoï.
A18: Địa chỉ, liên lạc | B18: vivre | C18: v | D18: sống
A19: Địa chỉ, liên lạc | B19: l'avenue | C19: nf | D19: đại lộ
A20: Địa chỉ, liên lạc | B20: l'arrondissement | C20: nm | D20: quận (ở các thành phố lớn như Paris)
A21: Tình trạng gia đình | B21: célibataire | C21: adj | D21: độc thân
A22: Tình trạng gia đình | B22: marié / mariée | C22: adj | D22: đã kết hôn
A23: Tình trạng gia đình | B23: divorcé / divorcée | C23: adj | D23: đã ly hôn
A24: Tình trạng gia đình | B24: veuf / veuve | C24: adj | D24: góa
A25: Tình trạng gia đình | B25: la situation de famille | C25: nf | D25: tình trạng hôn nhân
A26: Giấy tờ, biểu mẫu | B26: remplir un formulaire | C26: expr | D26: điền vào mẫu đơn
A27: Giấy tờ, biểu mẫu | B27: signer | C27: v | D27: ký tên
A28: Giấy tờ, biểu mẫu | B28: la carte d'identité | C28: nf | D28: thẻ căn cước
A29: Giấy tờ, biểu mẫu | B29: le passeport | C29: nm | D29: hộ chiếu
... A45: Quốc gia và quốc tịch | B45: italien / italienne | C45: adj | D45: người Ý
A46: Quốc gia và quốc tịch | B46: la France | C46: np f | D46: nước Pháp | E46: en France
A47: Quốc gia và quốc tịch | B47: le Viêt Nam | C47: np m | D47: Việt Nam | E47: au Viêt Nam
A48: Quốc gia và quốc tịch | B48: l'Angleterre | C48: np f | D48: nước Anh | E48: en Angleterre
A49: Quốc gia và quốc tịch | B49: les États-Unis | C49: np m pl | D49: Hoa Kỳ | E49: aux États-Unis
A50: Quốc gia và quốc tịch | B50: la Chine | C50: np f | D50: Trung Quốc | E50: en Chine
A51: Quốc gia và quốc tịch | B51: le Japon | C51: np m | D51: Nhật Bản | E51: au Japon
A52: Quốc gia và quốc tịch | B52: la Corée du Sud | C52: np f | D52: Hàn Quốc | E52: en Corée du Sud
A53: Quốc gia và quốc tịch | B53: l'Allemagne | C53: np f | D53: nước Đức | E53: en Allemagne
A54: Quốc gia và quốc tịch | B54: l'Espagne | C54: np f | D54: Tây Ban Nha | E54: en Espagne
A55: Quốc gia và quốc tịch | B55: l'Italie | C55: np f | D55: nước Ý | E55: en Italie
...

Sheet T03_NgheNghiep
A1: Nhóm con | B1: Tiếng Pháp | C1: Loại từ | D1: Nghĩa tiếng Việt | E1: Ghi chú
A2: Khái niệm chung về nghề | B2: le métier | C2: nm | D2: nghề, công việc chuyên môn
A3: Khái niệm chung về nghề | B3: la profession | C3: nf | D3: nghề nghiệp | E3: Je suis médecin. (không dùng mạo từ)
A4: Khái niệm chung về nghề | B4: le travail | C4: nm | D4: công việc
A5: Khái niệm chung về nghề | B5: travailler | C5: v | D5: làm việc
A6: Khái niệm chung về nghề | B6: le bureau | C6: nm | D6: văn phòng
A7: Khái niệm chung về nghề | B7: l'entreprise | C7: nf | D7: công ty
A8: Khái niệm chung về nghề | B8: Quel est votre métier ? | C8: expr | D8: Nghề của bạn là gì?
A9: Khái niệm chung về nghề | B9: l'emploi | C9: nm | D9: việc làm
A10: Khái niệm chung về nghề | B10: la société | C10: nf | D10: công ty
A11: Khái niệm chung về nghề | B11: l'usine | C11: nf | D11: nhà máy
A12: Khái niệm chung về nghề | B12: l'horaire | C12: nm | D12: giờ làm việc | E12: thường dùng số nhiều: les horaires
A13: Khái niệm chung về nghề | B13: le salaire | C13: nm | D13: tiền lương
A14: Khái niệm chung về nghề | B14: le patron / la patronne | C14: nm/nf | D14: ông chủ, bà chủ
A15: Khái niệm chung về nghề | B15: le chef | C15: nm | D15: sếp; người đứng đầu
A16: Khái niệm chung về nghề | B16: le collègue / la collègue | C16: nm/nf | D16: đồng nghiệp
A17: Khái niệm chung về nghề | B17: Qu'est-ce que vous faites dans la vie ? | C17: expr | D17: Bạn làm nghề gì?
A18: Học tập, giáo dục | B18: l'étudiant / l'étudiante | C18: nm/nf | D18: sinh viên
A19: Học tập, giáo dục | B19: l'élève | C19: nm/nf | D19: học sinh
A20: Học tập, giáo dục | B20: le professeur / la professeure | C20: nm/nf | D20: giáo viên; giáo sư
A21: Học tập, giáo dục | B21: l'enseignant / l'enseignante | C21: nm/nf | D21: giáo viên
A22: Học tập, giáo dục | B22: l'instituteur / l'institutrice | C22: nm/nf | D22: giáo viên tiểu học
A23: Y tế | B23: le médecin | C23: nm | D23: bác sĩ | E23: dùng chung cho nam và nữ
A24: Y tế | B24: l'infirmier / l'infirmière | C24: nm/nf | D24: y tá
A25: Y tế | B25: le dentiste / la dentiste | C25: nm/nf | D25: nha sĩ
A26: Y tế | B26: le pharmacien / la pharmacienne | C26: nm/nf | D26: dược sĩ
A27: Y tế | B27: le docteur | C27: nm | D27: bác sĩ (cách gọi)
A28: Y tế | B28: le chirurgien / la chirurgienne | C28: nm/nf | D28: bác sĩ phẫu thuật
A29: Y tế | B29: le patient / la patiente | C29: nm/nf | D29: bệnh nhân
A30: Văn phòng, luật, kỹ thuật | B30: l'avocat / l'avocate | C30: nm/nf | D30: luật sư
A31: Văn phòng, luật, kỹ thuật | B31: l'ingénieur / l'ingénieure | C31: nm/nf | D31: kỹ sư
A32: Văn phòng, luật, kỹ thuật | B32: le comptable / la comptable | C32: nm/nf | D32: kế toán
A33: Văn phòng, luật, kỹ thuật | B33: le secrétaire / la secrétaire | C33: nm/nf | D33: thư ký
A34: Văn phòng, luật, kỹ thuật | B34: l'employé / l'employée | C34: nm/nf | D34: nhân viên
A35: Văn phòng, luật, kỹ thuật | B35: le directeur / la directrice | C35: nm/nf | D35: giám đốc
... A67: Tình trạng việc làm | B67: la retraite | C67: nf | D67: hưu trí

Sheet T04_GiaDinh
A1: Nhóm con | B1: Tiếng Pháp | C1: Loại từ | D1: Nghĩa tiếng Việt | E1: Ghi chú
A2: Gia đình hạt nhân | B2: la famille | C2: nf | D2: gia đình
A3: Gia đình hạt nhân | B3: les parents | C3: nm pl | D3: bố mẹ
A4: Gia đình hạt nhân | B4: le père | C4: nm | D4: bố
A5: Gia đình hạt nhân | B5: la mère | C5: nf | D5: mẹ
A6: Gia đình hạt nhân | B6: le papa | C6: nm | D6: ba, bố (thân mật)
A7: Gia đình hạt nhân | B7: la maman | C7: nf | D7: mẹ (thân mật)
A8: Gia đình hạt nhân | B8: le fils | C8: nm | D8: con trai
A9: Gia đình hạt nhân | B9: la fille | C9: nf | D9: con gái; cô gái
A10: Gia đình hạt nhân | B10: l'enfant | C10: nm/nf | D10: đứa trẻ; con
A11: Gia đình hạt nhân | B11: le frère | C11: nm | D11: anh/em trai
A12: Gia đình hạt nhân | B12: la sœur | C12: nf | D12: chị/em gái
A13: Gia đình hạt nhân | B13: l'arbre généalogique | C13: nm | D13: cây gia phả
... A18: Ông bà, cháu | B18: la petite-fille | C18: nf | D18: cháu gái (của ông bà)
A19: Ông bà, cháu | B19: le papi | C19: nm | D19: ông (thân mật) | E19: thân mật
A20: Ông bà, cháu | B20: la mamie | C20: nf | D20: bà (thân mật) | E20: thân mật
A21: Ông bà, cháu | B21: les petits-enfants | C21: nm pl | D21: các cháu (của ông bà)
A22: Họ hàng | B22: l'oncle | C22: nm | D22: chú, bác, cậu
A23: Họ hàng | B23: la tante | C23: nf | D23: cô, dì, bác gái
A24: Họ hàng | B24: le cousin | C24: nm | D24: anh/em họ (nam)
A25: Họ hàng | B25: la cousine | C25: nf | D25: chị/em họ (nữ)
A26: Họ hàng | B26: le neveu | C26: nm | D26: cháu trai (của cô, chú)
A27: Họ hàng | B27: la nièce | C27: nf | D27: cháu gái (của cô, chú)
A28: Họ hàng | B28: le tonton | C28: nm | D28: chú/bác/cậu (thân mật) | E28: thân mật
A29: Họ hàng | B29: la tatie | C29: nf | D29: cô/dì (thân mật) | E29: cũng nói: la tata
A30: Vợ chồng, nhà vợ/chồng | B30: le mari | C30: nm | D30: chồng
A31: Vợ chồng, nhà vợ/chồng | B31: la femme | C31: nf | D31: vợ; phụ nữ | E31: ma femme = vợ tôi
A32: Vợ chồng, nhà vợ/chồng | B32: le beau-père | C32: nm | D32: bố chồng/bố vợ; bố dượng
A33: Vợ chồng, nhà vợ/chồng | B33: la belle-mère | C33: nf | D33: mẹ chồng/mẹ vợ; mẹ kế
A34: Vợ chồng, nhà vợ/chồng | B34: la belle-fille | C34: nf | D34: con dâu
A35: Vợ chồng, nhà vợ/chồng | B35: le gendre | C35: nm | D35: con rể
A36: Vợ chồng, nhà vợ/chồng | B36: les beaux-parents | C36: nm pl | D36: bố mẹ chồng/bố mẹ vợ
A37: Vợ chồng, nhà vợ/chồng | B37: le beau-frère | C37: nm | D37: anh/em rể; anh/em vợ/chồng
A38: Vợ chồng, nhà vợ/chồng | B38: la belle-sœur | C38: nf | D38: chị/em dâu; chị/em vợ/chồng
A39: Vợ chồng, nhà vợ/chồng | B39: le compagnon / la compagne | C39: nm/nf | D39: bạn đời
A40: Vợ chồng, nhà vợ/chồng | B40: le couple | C40: nm | D40: cặp đôi
A41: Độ tuổi, các giai đoạn cuộc đời | B41: l'homme | C41: nm | D41: đàn ông
A42: Độ tuổi, các giai đoạn cuộc đời | B42: le garçon | C42: nm | D42: cậu bé; con trai
A43: Độ tuổi, các giai đoạn cuộc đời | B43: le bébé | C43: nm | D43: em bé
... A46: Độ tuổi, các giai đoạn cuộc đời | B46: vieux / vieille | C46: adj | D46: già; cũ
...

Sheet T05_ThoiGian
A1: Nhóm con | B1: Tiếng Pháp | C1: Loại từ | D1: Nghĩa tiếng Việt | E1: Ghi chú
A2: Đơn vị thời gian | B2: le jour | C2: nm | D2: ngày
A3: Đơn vị thời gian | B3: la semaine | C3: nf | D3: tuần
A4: Đơn vị thời gian | B4: le mois | C4: nm | D4: tháng
A5: Đơn vị thời gian | B5: l'année | C5: nf | D5: năm
A6: Đơn vị thời gian | B6: la date | C6: nf | D6: ngày tháng | E6: Quelle est la date ?
A7: Các ngày trong tuần | B7: lundi | C7: nm | D7: thứ Hai
A8: Các ngày trong tuần | B8: mardi | C8: nm | D8: thứ Ba
A9: Các ngày trong tuần | B9: mercredi | C9: nm | D9: thứ Tư
A10: Các ngày trong tuần | B10: jeudi | C10: nm | D10: thứ Năm
A11: Các ngày trong tuần | B11: vendredi | C11: nm | D11: thứ Sáu
A12: Các ngày trong tuần | B12: samedi | C12: nm | D12: thứ Bảy
A13: Các ngày trong tuần | B13: dimanche | C13: nm | D13: Chủ nhật
A14: Các ngày trong tuần | B14: le week-end | C14: nm | D14: cuối tuần
A15: Các tháng | B15: janvier | C15: nm | D15: tháng Một
A16: Các tháng | B16: février | C16: nm | D16: tháng Hai
A17: Các tháng | B17: mars | C17: nm | D17: tháng Ba
A18: Các tháng | B18: avril | C18: nm | D18: tháng Tư
... A32: Các buổi trong ngày | B32: le matin | C32: nm | D32: buổi sáng
A33: Các buổi trong ngày | B33: l'après-midi | C33: nm/nf | D33: buổi chiều | E33: dùng được cả giống đực và giống cái
A34: Các buổi trong ngày | B34: le soir | C34: nm | D34: buổi tối
A35: Các buổi trong ngày | B35: la nuit | C35: nf | D35: đêm
A36: Các buổi trong ngày | B36: la journée | C36: nf | D36: cả ngày; ban ngày
A37: Giờ giấc | B37: l'heure | C37: nf | D37: giờ
A38: Giờ giấc | B38: la minute | C38: nf | D38: phút
A39: Giờ giấc | B39: midi | C39: nm | D39: buổi trưa; 12 giờ trưa
A40: Giờ giấc | B40: minuit | C40: nm | D40: nửa đêm
A41: Giờ giấc | B41: Quelle heure est-il ? | C41: expr | D41: Mấy giờ rồi?
A42: Giờ giấc | B42: et quart | C42: expr | D42: …giờ mười lăm | E42: Il est trois heures et quart.
A43: Giờ giấc | B43: et demie | C43: expr | D43: …giờ rưỡi
A44: Giờ giấc | B44: moins le quart | C44: expr | D44: …giờ kém mười lăm
A45: Giờ giấc | B45: la demi-heure | C45: nf | D45: nửa tiếng
A46: Giờ giấc | B46: le quart d'heure | C46: nm | D46: mười lăm phút
A47: Trạng từ thời gian | B47: aujourd'hui | C47: adv | D47: hôm nay
A48: Trạng từ thời gian | B48: demain | C48: adv | D48: ngày mai
A49: Trạng từ thời gian | B49: hier | C49: adv | D49: hôm qua
A50: Trạng từ thời gian | B50: maintenant | C50: adv | D50: bây giờ
A51: Trạng từ thời gian | B51: tôt | C51: adv | D51: sớm
A52: Trạng từ thời gian | B52: tard | C52: adv | D52: muộn
A53: Trạng từ thời gian | B53: pendant | C53: prép | D53: trong suốt
...

Sheet T06_HangNgay
A1: Nhóm con | B1: Tiếng Pháp | C1: Loại từ | D1: Nghĩa tiếng Việt | E1: Ghi chú
A2: Buổi sáng, vệ sinh cá nhân | B2: se réveiller | C2: v | D2: thức dậy | E2: động từ phản thân
A3: Buổi sáng, vệ sinh cá nhân | B3: se lever | C3: v | D3: ngủ dậy; đứng dậy | E3: động từ phản thân
A4: Buổi sáng, vệ sinh cá nhân | B4: se laver | C4: v | D4: tắm rửa; rửa mặt | E4: động từ phản thân
A5: Buổi sáng, vệ sinh cá nhân | B5: prendre une douche | C5: expr | D5: tắm vòi sen
A6: Buổi sáng, vệ sinh cá nhân | B6: se brosser les dents | C6: expr | D6: đánh răng
A7: Buổi sáng, vệ sinh cá nhân | B7: s'habiller | C7: v | D7: mặc quần áo | E7: động từ phản thân
A8: Buổi sáng, vệ sinh cá nhân | B8: se maquiller | C8: v | D8: trang điểm | E8: động từ phản thân
A9: Buổi sáng, vệ sinh cá nhân | B9: se coiffer | C9: v | D9: chải đầu | E9: động từ phản thân
A10: Buổi sáng, vệ sinh cá nhân | B10: se laver les mains | C10: expr | D10: rửa tay
A11: Buổi sáng, vệ sinh cá nhân | B11: le dentifrice | C11: nm | D11: kem đánh răng
A12: Bữa ăn | B12: le petit déjeuner | C12: nm | D12: bữa sáng
A13: Bữa ăn | B13: déjeuner | C13: v | D13: ăn trưa
A14: Bữa ăn | B14: le déjeuner | C14: nm | D14: bữa trưa
A15: Bữa ăn | B15: dîner | C15: v | D15: ăn tối
A16: Bữa ăn | B16: le dîner | C16: nm | D16: bữa tối
A17: Học, làm việc, giải trí | B17: étudier | C17: v | D17: học
A18: Học, làm việc, giải trí | B18: aller à l'école | C18: expr | D18: đi học
A19: Học, làm việc, giải trí | B19: aller au travail | C19: expr | D19: đi làm
A20: Học, làm việc, giải trí | B20: rentrer | C20: v | D20: về nhà
A21: Học, làm việc, giải trí | B21: se reposer | C21: v | D21: nghỉ ngơi
... A26: Học, làm việc, giải trí | B26: téléphoner | C26: v | D26: gọi điện thoại
A27: Học, làm việc, giải trí | B27: se promener | C27: v | D27: đi dạo | E27: động từ phản thân
A28: Học, làm việc, giải trí | B28: commencer | C28: v | D28: bắt đầu
A29: Học, làm việc, giải trí | B29: finir | C29: v | D29: kết thúc
A30: Học, làm việc, giải trí | B30: écrire | C30: v | D30: viết
A31: Học, làm việc, giải trí | B31: ouvrir | C31: v | D31: mở
A32: Học, làm việc, giải trí | B32: fermer | C32: v | D32: đóng
A33: Học, làm việc, giải trí | B33: allumer | C33: v | D33: bật (đèn, ti vi)
A34: Học, làm việc, giải trí | B34: éteindre | C34: v | D34: tắt
A35: Học, làm việc, giải trí | B35: chercher | C35: v | D35: tìm; đón
A36: Học, làm việc, giải trí | B36: accompagner | C36: v | D36: đi cùng; đưa đi
A37: Học, làm việc, giải trí | B37: répondre | C37: v | D37: trả lời
A38: Học, làm việc, giải trí | B38: le journal | C38: nm | D38: báo; bản tin
A39: Học, làm việc, giải trí | B39: le courrier | C39: nm | D39: thư từ
... A49: Việc nhà | B49: préparer le repas | C49: expr | D49: chuẩn bị bữa ăn
A50: Buổi tối, đi ngủ | B50: se coucher | C50: v | D50: đi ngủ | E50: động từ phản thân
A51: Buổi tối, đi ngủ | B51: dormir | C51: v | D51: ngủ
A52: Tần suất | B52: toujours | C52: adv | D52: luôn luôn
A53: Tần suất | B53: souvent | C53: adv | D53: thường
...

Sheet T07_NhaCua
A1: Nhóm con | B1: Tiếng Pháp | C1: Loại từ | D1: Nghĩa tiếng Việt | E1: Ghi chú
A2: Loại nhà ở | B2: la maison | C2: nf | D2: nhà (nhà riêng)
A3: Loại nhà ở | B3: l'appartement | C3: nm | D3: căn hộ
A4: Loại nhà ở | B4: l'immeuble | C4: nm | D4: tòa nhà chung cư
A5: Loại nhà ở | B5: le logement | C5: nm | D5: chỗ ở
A6: Loại nhà ở | B6: le studio | C6: nm | D6: căn hộ studio
A7: Loại nhà ở | B7: le deux-pièces | C7: nm | D7: căn hộ hai phòng
A8: Các phòng | B8: la pièce | C8: nf | D8: phòng (nói chung)
A9: Các phòng | B9: le salon | C9: nm | D9: phòng khách
A10: Các phòng | B10: la salle à manger | C10: nf | D10: phòng ăn
A11: Các phòng | B11: la cuisine | C11: nf | D11: nhà bếp | E11: faire la cuisine = nấu ăn
A12: Các phòng | B12: la chambre | C12: nf | D12: phòng ngủ
A13: Các phòng | B13: la salle de bains | C13: nf | D13: phòng tắm
A14: Các phòng | B14: les toilettes | C14: nf pl | D14: nhà vệ sinh
A15: Các phòng | B15: l'entrée | C15: nf | D15: lối vào; sảnh
A16: Các phòng | B16: le couloir | C16: nm | D16: hành lang
A17: Các phòng | B17: le balcon | C17: nm | D17: ban công
A18: Các phòng | B18: le jardin | C18: nm | D18: vườn
A19: Các phòng | B19: le garage | C19: nm | D19: ga-ra
A20: Các phòng | B20: le séjour | C20: nm | D20: phòng khách, phòng sinh hoạt chung
A21: Cấu trúc tòa nhà | B21: l'étage | C21: nm | D21: tầng (lầu)
A22: Cấu trúc tòa nhà | B22: le rez-de-chaussée | C22: nm | D22: tầng trệt
A23: Cấu trúc tòa nhà | B23: l'escalier | C23: nm | D23: cầu thang
... A55: Thuê nhà, hàng xóm | B55: l'agence immobilière | C55: nf | D55: công ty môi giới nhà đất
A56: Tính chất nhà ở | B56: calme | C56: adj | D56: yên tĩnh | E56: không đổi giống
A57: Tính chất nhà ở | B57: bruyant / bruyante | C57: adj | D57: ồn ào
A58: Tính chất nhà ở | B58: confortable | C58: adj | D58: tiện nghi, thoải mái | E58: không đổi giống
A59: Tính chất nhà ở | B59: moderne | C59: adj | D59: hiện đại | E59: không đổi giống
A60: Tính chất nhà ở | B60: ancien / ancienne | C60: adj | D60: cũ, cổ
A61: Tính chất nhà ở | B61: meublé / meublée | C61: adj | D61: có sẵn nội thất
A62: Tính chất nhà ở | B62: le mètre carré | C62: nm | D62: mét vuông
A63: Thiết bị, tiện ích | B63: le réfrigérateur | C63: nm | D63: tủ lạnh | E63: nói tắt: le frigo (thân mật)
A64: Thiết bị, tiện ích | B64: la lumière | C64: nf | D64: ánh sáng; đèn
A65: Thiết bị, tiện ích | B65: le four | C65: nm | D65: lò nướng
A66: Thiết bị, tiện ích | B66: l'aspirateur | C66: nm | D66: máy hút bụi
A67: Thiết bị, tiện ích | B67: la machine à laver | C67: nf | D67: máy giặt
A68: Thiết bị, tiện ích | B68: le balai | C68: nm | D68: cái chổi
A69: Thiết bị, tiện ích | B69: le chauffage | C69: nm | D69: hệ thống sưởi
A70: Thiết bị, tiện ích | B70: l'électricité | C70: nf | D70: điện
A71: Thiết bị, tiện ích | B71: le gaz | C71: nm | D71: khí đốt

Sheet T08_ThanhPho
A1: Nhóm con | B1: Tiếng Pháp | C1: Loại từ | D1: Nghĩa tiếng Việt | E1: Ghi chú
A2: Thành phố, khu phố | B2: la ville | C2: nf | D2: thành phố
A3: Thành phố, khu phố | B3: le village | C3: nm | D3: làng
A4: Thành phố, khu phố | B4: la campagne | C4: nf | D4: nông thôn
A5: Thành phố, khu phố | B5: le quartier | C5: nm | D5: khu phố
A6: Thành phố, khu phố | B6: la rue | C6: nf | D6: con đường, phố
A7: Thành phố, khu phố | B7: la place | C7: nf | D7: quảng trường
A8: Thành phố, khu phố | B8: le centre-ville | C8: nm | D8: trung tâm thành phố
A9: Ga, bến, sân bay | B9: la gare | C9: nf | D9: ga tàu
A10: Ga, bến, sân bay | B10: la station de métro | C10: nf | D10: ga tàu điện ngầm
A11: Ga, bến, sân bay | B11: l'arrêt de bus | C11: nm | D11: trạm xe buýt
A12: Ga, bến, sân bay | B12: l'aéroport | C12: nm | D12: sân bay
A13: Ga, bến, sân bay | B13: le quai | C13: nm | D13: sân ga; bến
... A23: Địa điểm, cửa hàng | B23: le restaurant | C23: nm | D23: nhà hàng
A24: Địa điểm, cửa hàng | B24: le café | C24: nm | D24: quán cà phê | E24: còn nghĩa "cà phê" (đồ uống): xem chủ đề 10
A25: Địa điểm, cửa hàng | B25: le musée | C25: nm | D25: bảo tàng
A26: Địa điểm, cửa hàng | B26: le cinéma | C26: nm | D26: rạp chiếu phim
A27: Địa điểm, cửa hàng | B27: le parc | C27: nm | D27: công viên
A28: Địa điểm, cửa hàng | B28: la mairie | C28: nf | D28: tòa thị chính
A29: Địa điểm, cửa hàng | B29: le pont | C29: nm | D29: cây cầu
A30: Địa điểm, cửa hàng | B30: la cathédrale | C30: nf | D30: nhà thờ lớn
A31: Địa điểm, cửa hàng | B31: le château | C31: nm | D31: lâu đài
A32: Chỉ đường | B32: à droite | C32: expr | D32: bên phải; rẽ phải
A33: Chỉ đường | B33: à gauche | C33: expr | D33: bên trái; rẽ trái
A34: Chỉ đường | B34: tout droit | C34: expr | D34: đi thẳng
A35: Chỉ đường | B35: tourner | C35: v | D35: rẽ
A36: Chỉ đường | B36: traverser | C36: v | D36: băng qua
... A90: Phương hướng | B90: l'ouest | C90: nm | D90: phía tây

Sheet T09_QuanAo
A1: Nhóm con | B1: Tiếng Pháp | C1: Loại từ | D1: Nghĩa tiếng Việt | E1: Ghi chú
A2: Màu sắc | B2: la couleur | C2: nf | D2: màu sắc
A3: Màu sắc | B3: rouge | C3: adj | D3: đỏ
A4: Màu sắc | B4: bleu / bleue | C4: adj | D4: xanh dương
A5: Màu sắc | B5: vert / verte | C5: adj | D5: xanh lá
A6: Màu sắc | B6: jaune | C6: adj | D6: vàng
A7: Màu sắc | B7: noir / noire | C7: adj | D7: đen
A8: Màu sắc | B8: blanc / blanche | C8: adj | D8: trắng
A9: Màu sắc | B9: gris / grise | C9: adj | D9: xám
A10: Màu sắc | B10: orange | C10: adj | D10: cam | E10: bất biến (không đổi giống, số)
A11: Màu sắc | B11: rose | C11: adj | D11: hồng
A12: Màu sắc | B12: violet / violette | C12: adj | D12: tím
A13: Màu sắc | B13: marron | C13: adj | D13: nâu | E13: bất biến (không đổi giống, số)
A14: Màu sắc | B14: clair / claire | C14: adj | D14: sáng (màu) | E14: vert clair
A15: Màu sắc | B15: foncé / foncée | C15: adj | D15: đậm (màu) | E15: bleu foncé
A16: Quần áo, giày dép | B16: le vêtement | C16: nm | D16: quần áo (một món)
A17: Quần áo, giày dép | B17: le pantalon | C17: nm | D17: quần dài
A18: Quần áo, giày dép | B18: le jean | C18: nm | D18: quần jean
A19: Quần áo, giày dép | B19: la jupe | C19: nf | D19: chân váy
A20: Quần áo, giày dép | B20: la robe | C20: nf | D20: váy liền, đầm
A21: Quần áo, giày dép | B21: la chemise | C21: nf | D21: áo sơ mi
A22: Quần áo, giày dép | B22: le tee-shirt | C22: nm | D22: áo thun
A23: Quần áo, giày dép | B23: le pull | C23: nm | D23: áo len
A24: Quần áo, giày dép | B24: la veste | C24: nf | D24: áo khoác ngắn
A25: Quần áo, giày dép | B25: le manteau | C25: nm | D25: áo khoác dài
A26: Quần áo, giày dép | B26: l'imperméable | C26: nm | D26: áo mưa
A27: Quần áo, giày dép | B27: les chaussures | C27: nf pl | D27: giày
... A50: Mặc, thử, cỡ số | B50: la mode | C50: nf | D50: thời trang
A51: Mặc, thử, cỡ số | B51: chic | C51: adj | D51: sang, lịch sự | E51: không đổi giống
A52: Chất liệu | B52: la laine | C52: nf | D52: len
A53: Chất liệu | B53: le coton | C53: nm | D53: cotton
A54: Chất liệu | B54: le cuir | C54: nm | D54: da thuộc
A55: Miêu tả ngoại hình | B55: grand / grande | C55: adj | D55: cao; to
A56: Miêu tả ngoại hình | B56: petit / petite | C56: adj | D56: thấp; nhỏ
A57: Miêu tả ngoại hình | B57: gros / grosse | C57: adj | D57: mập; to
A58: Miêu tả ngoại hình | B58: mince | C58: adj | D58: gầy, thon
A59: Miêu tả ngoại hình | B59: beau / belle | C59: adj | D59: đẹp
A60: Miêu tả ngoại hình | B60: joli / jolie | C60: adj | D60: xinh
A61: Miêu tả ngoại hình | B61: laid / laide | C61: adj | D61: xấu
A62: Miêu tả ngoại hình | B62: maigre | C62: adj | D62: gầy (còm) | E62: không đổi giống
...

Sheet T10_AnUong
A1: Nhóm con | B1: Tiếng Pháp | C1: Loại từ | D1: Nghĩa tiếng Việt | E1: Ghi chú
A2: Đồ uống | B2: l'eau | C2: nf | D2: nước
A3: Đồ uống | B3: le café | C3: nm | D3: cà phê (đồ uống)
A4: Đồ uống | B4: le thé | C4: nm | D4: trà
A5: Đồ uống | B5: le lait | C5: nm | D5: sữa
A6: Đồ uống | B6: le jus d'orange | C6: nm | D6: nước cam ép
A7: Đồ uống | B7: le vin | C7: nm | D7: rượu vang
A8: Đồ uống | B8: la boisson | C8: nf | D8: đồ uống
A9: Đồ uống | B9: la bière | C9: nf | D9: bia
A10: Đồ uống | B10: l'alcool | C10: nm | D10: rượu bia
A11: Bánh mì, trứng, sữa | B11: le pain | C11: nm | D11: bánh mì
A12: Bánh mì, trứng, sữa | B12: la baguette | C12: nf | D12: bánh mì que Pháp
A13: Bánh mì, trứng, sữa | B13: le fromage | C13: nm | D13: phô mai
A14: Bánh mì, trứng, sữa | B14: le beurre | C14: nm | D14: bơ
A15: Bánh mì, trứng, sữa | B15: l'œuf | C15: nm | D15: trứng | E15: số nhiều: les œufs
A16: Bánh mì, trứng, sữa | B16: le yaourt | C16: nm | D16: sữa chua
A17: Bánh mì, trứng, sữa | B17: le croissant | C17: nm | D17: bánh sừng bò
A18: Bánh mì, trứng, sữa | B18: la farine | C18: nf | D18: bột mì
A19: Thịt, cá, hải sản | B19: la viande | C19: nf | D19: thịt
A20: Thịt, cá, hải sản | B20: le poulet | C20: nm | D20: thịt gà
A21: Thịt, cá, hải sản | B21: le poisson | C21: nm | D21: cá
A22: Thịt, cá, hải sản | B22: le jambon | C22: nm | D22: giăm bông
A23: Thịt, cá, hải sản | B23: le porc | C23: nm | D23: thịt heo
A24: Thịt, cá, hải sản | B24: le bœuf | C24: nm | D24: thịt bò
A25: Thịt, cá, hải sản | B25: le canard | C25: nm | D25: vịt
A26: Thịt, cá, hải sản | B26: le saumon | C26: nm | D26: cá hồi
A27: Thịt, cá, hải sản | B27: le thon | C27: nm | D27: cá ngừ
... A60: Bữa ăn, nhà hàng | B60: le dessert | C60: nm | D60: món tráng miệng
A61: Bữa ăn, nhà hàng | B61: le menu | C61: nm | D61: thực đơn trọn gói | E61: thực đơn gọi món: la carte
A62: Bữa ăn, nhà hàng | B62: l'addition | C62: nf | D62: hóa đơn (nhà hàng)
A63: Bữa ăn, nhà hàng | B63: manger | C63: v | D63: ăn
A64: Bữa ăn, nhà hàng | B64: boire | C64: v | D64: uống
A65: Bữa ăn, nhà hàng | B65: avoir faim | C65: expr | D65: đói
A66: Bữa ăn, nhà hàng | B66: avoir soif | C66: expr | D66: khát
A67: Bữa ăn, nhà hàng | B67: commander | C67: v | D67: gọi món
A68: Bữa ăn, nhà hàng | B68: emporter | C68: v | D68: mang đi
A69: Bữa ăn, nhà hàng | B69: le plat | C69: nm | D69: món ăn; đĩa lớn
A70: Bữa ăn, nhà hàng | B70: la recette | C70: nf | D70: công thức nấu ăn
A71: Bữa ăn, nhà hàng | B71: l'aliment | C71: nm | D71: thực phẩm
A72: Bát đĩa, dụng cụ ăn | B72: l'assiette | C72: nf | D72: cái đĩa
...

Sheet T11_SoThich
A1: Nhóm con | B1: Tiếng Pháp | C1: Loại từ | D1: Nghĩa tiếng Việt | E1: Ghi chú
A2: Sở thích, thích/ghét | B2: le loisir | C2: nm | D2: thú vui; hoạt động giải trí
A3: Sở thích, thích/ghét | B3: aimer | C3: v | D3: thích; yêu
A4: Sở thích, thích/ghét | B4: adorer | C4: v | D4: rất thích
A5: Sở thích, thích/ghét | B5: détester | C5: v | D5: ghét
A6: Sở thích, thích/ghét | B6: préférer | C6: v | D6: thích hơn
A7: Sở thích, thích/ghét | B7: s'amuser | C7: v | D7: vui chơi | E7: động từ phản thân
A8: Sở thích, thích/ghét | B8: sortir | C8: v | D8: ra ngoài; đi chơi
A9: Thể thao | B9: jouer | C9: v | D9: chơi
A10: Thể thao | B10: le sport | C10: nm | D10: thể thao
A11: Thể thao | B11: le football | C11: nm | D11: bóng đá
A12: Thể thao | B12: le tennis | C12: nm | D12: quần vợt
A13: Thể thao | B13: le basket | C13: nm | D13: bóng rổ
A14: Thể thao | B14: la natation | C14: nf | D14: bơi lội
A15: Thể thao | B15: nager | C15: v | D15: bơi
A16: Thể thao | B16: courir | C16: v | D16: chạy
A17: Thể thao | B17: faire du vélo | C17: expr | D17: đạp xe
A18: Thể thao | B18: faire du sport | C18: expr | D18: chơi thể thao
A19: Thể thao | B19: la randonnée | C19: nf | D19: đi bộ đường dài
... A34: Văn hóa, trò chơi | B34: le livre | C34: nm | D34: quyển sách
A35: Văn hóa, trò chơi | B35: le jeu | C35: nm | D35: trò chơi | E35: số nhiều: les jeux
A36: Văn hóa, trò chơi | B36: le jeu vidéo | C36: nm | D36: trò chơi điện tử
A37: Văn hóa, trò chơi | B37: la photo | C37: nf | D37: bức ảnh
A38: Văn hóa, trò chơi | B38: la peinture | C38: nf | D38: hội họa; tranh
A39: Văn hóa, trò chơi | B39: le dessin | C39: nm | D39: bức vẽ; môn vẽ
A40: Văn hóa, trò chơi | B40: la lecture | C40: nf | D40: việc đọc sách
A41: Văn hóa, trò chơi | B41: la guitare | C41: nf | D41: đàn ghi-ta
A42: Văn hóa, trò chơi | B42: le concert | C42: nm | D42: buổi hòa nhạc
A43: Văn hóa, trò chơi | B43: le spectacle | C43: nm | D43: buổi biểu diễn
A44: Văn hóa, trò chơi | B44: la discothèque | C44: nf | D44: vũ trường
A45: Văn hóa, trò chơi | B45: la bibliothèque | C45: nf | D45: thư viện
A46: Văn hóa, trò chơi | B46: les cartes | C46: nf pl | D46: bài tây | E46: jouer aux cartes
A47: Văn hóa, trò chơi | B47: les échecs | C47: nm pl | D47: cờ vua
A48: Văn hóa, trò chơi | B48: le jouet | C48: nm | D48: đồ chơi
A49: Văn hóa, trò chơi | B49: l'appareil photo | C49: nm | D49: máy ảnh
A50: Thời tiết | B50: le temps | C50: nm | D50: thời tiết; thời gian
A51: Thời tiết | B51: Quel temps fait-il ? | C51: expr | D51: Thời tiết thế nào?
A52: Thời tiết | B52: Il fait beau. | C52: expr | D52: Trời đẹp.
A53: Thời tiết | B53: Il fait mauvais. | C53: expr | D53: Trời xấu.
A54: Thời tiết | B54: Il fait chaud. | C54: expr | D54: Trời nóng.
...
